Internal Server Error: /moodle/fetch-users/
Traceback (most recent call last):
  File "C:\Users\MAVIDIA\AppData\Local\Programs\Python\Python312\Lib\site-packages\django\core\handlers\exception.py", line 55, in inner
    response = get_response(request)
               ^^^^^^^^^^^^^^^^^^^^^
  File "C:\Users\MAVIDIA\AppData\Local\Programs\Python\Python312\Lib\site-packages\django\core\handlers\base.py", line 197, in _get_response
    response = wrapped_callback(request, *callback_args, **callback_kwargs)
               ^^^^^^^^^^^^^^^^^^^^^^^^^^^^^^^^^^^^^^^^^^^^^^^^^^^^^^^^^^^^
  File "D:\Mavidia\projet\mon_projet\moodle\views.py", line 13, in trigger_fetch_users
    fetch_and_save_users.delay()
    ^^^^^^^^^^^^^^^^^^^^^^^^^^
AttributeError: 'function' object has no attribute 'delay'
"GET /moodle/fetch-users/ HTTP/1.1" 500 66558
Internal Server Error: /moodle/fetch-users/
Traceback (most recent call last):
  File "C:\Users\MAVIDIA\AppData\Local\Programs\Python\Python312\Lib\site-packages\django\core\handlers\exception.py", line 55, in inner
    response = get_response(request)
               ^^^^^^^^^^^^^^^^^^^^^
  File "C:\Users\MAVIDIA\AppData\Local\Programs\Python\Python312\Lib\site-packages\django\core\handlers\base.py", line 197, in _get_response
    response = wrapped_callback(request, *callback_args, **callback_kwargs)
               ^^^^^^^^^^^^^^^^^^^^^^^^^^^^^^^^^^^^^^^^^^^^^^^^^^^^^^^^^^^^
  File "D:\Mavidia\projet\mon_projet\moodle\views.py", line 13, in trigger_fetch_users
    fetch_and_save_users.delay()
    ^^^^^^^^^^^^^^^^^^^^^^^^^^
AttributeError: 'function' object has no attribute 'delay'
"GET /moodle/fetch-users/ HTTP/1.1" 500 66558
Internal Server Error: /moodle/fetch-users/
Traceback (most recent call last):
  File "C:\Users\MAVIDIA\AppData\Local\Programs\Python\Python312\Lib\site-packages\django\core\handlers\exception.py", line 55, in inner
    response = get_response(request)
               ^^^^^^^^^^^^^^^^^^^^^
  File "C:\Users\MAVIDIA\AppData\Local\Programs\Python\Python312\Lib\site-packages\django\core\handlers\base.py", line 197, in _get_response
    response = wrapped_callback(request, *callback_args, **callback_kwargs)
               ^^^^^^^^^^^^^^^^^^^^^^^^^^^^^^^^^^^^^^^^^^^^^^^^^^^^^^^^^^^^
  File "D:\Mavidia\projet\mon_projet\moodle\views.py", line 13, in trigger_fetch_users
    fetch_and_save_users.delay()
    ^^^^^^^^^^^^^^^^^^^^^^^^^^
AttributeError: 'function' object has no attribute 'delay'
"GET /moodle/fetch-users/ HTTP/1.1" 500 66557
Internal Server Error: /moodle/fetch-users/
Traceback (most recent call last):
  File "C:\Users\MAVIDIA\AppData\Local\Programs\Python\Python312\Lib\site-packages\redis\_parsers\socket.py", line 65, in _read_from_socket
    data = self._sock.recv(socket_read_size)
           ^^^^^^^^^^^^^^^^^^^^^^^^^^^^^^^^^
TimeoutError: timed out

During handling of the above exception, another exception occurred:

Traceback (most recent call last):
  File "C:\Users\MAVIDIA\AppData\Local\Programs\Python\Python312\Lib\site-packages\celery\backends\redis.py", line 127, in reconnect_on_error
    yield
  File "C:\Users\MAVIDIA\AppData\Local\Programs\Python\Python312\Lib\site-packages\celery\backends\redis.py", line 177, in _consume_from
    self._pubsub.subscribe(key)
  File "C:\Users\MAVIDIA\AppData\Local\Programs\Python\Python312\Lib\site-packages\redis\client.py", line 957, in subscribe
    ret_val = self.execute_command("SUBSCRIBE", *new_channels.keys())
              ^^^^^^^^^^^^^^^^^^^^^^^^^^^^^^^^^^^^^^^^^^^^^^^^^^^^^^^
  File "C:\Users\MAVIDIA\AppData\Local\Programs\Python\Python312\Lib\site-packages\redis\client.py", line 786, in execute_command
    self.connection = self.connection_pool.get_connection(
                      ^^^^^^^^^^^^^^^^^^^^^^^^^^^^^^^^^^^^
  File "C:\Users\MAVIDIA\AppData\Local\Programs\Python\Python312\Lib\site-packages\redis\connection.py", line 1422, in get_connection
    connection.connect()
  File "C:\Users\MAVIDIA\AppData\Local\Programs\Python\Python312\Lib\site-packages\redis\connection.py", line 369, in connect
    self.on_connect()
  File "C:\Users\MAVIDIA\AppData\Local\Programs\Python\Python312\Lib\site-packages\redis\connection.py", line 471, in on_connect
    self.read_response()
  File "C:\Users\MAVIDIA\AppData\Local\Programs\Python\Python312\Lib\site-packages\redis\connection.py", line 592, in read_response
    response = self._parser.read_response(disable_decoding=disable_decoding)
               ^^^^^^^^^^^^^^^^^^^^^^^^^^^^^^^^^^^^^^^^^^^^^^^^^^^^^^^^^^^^^
  File "C:\Users\MAVIDIA\AppData\Local\Programs\Python\Python312\Lib\site-packages\redis\_parsers\resp2.py", line 15, in read_response
    result = self._read_response(disable_decoding=disable_decoding)
             ^^^^^^^^^^^^^^^^^^^^^^^^^^^^^^^^^^^^^^^^^^^^^^^^^^^^^^
  File "C:\Users\MAVIDIA\AppData\Local\Programs\Python\Python312\Lib\site-packages\redis\_parsers\resp2.py", line 25, in _read_response
    raw = self._buffer.readline()
          ^^^^^^^^^^^^^^^^^^^^^^^
  File "C:\Users\MAVIDIA\AppData\Local\Programs\Python\Python312\Lib\site-packages\redis\_parsers\socket.py", line 115, in readline
    self._read_from_socket()
  File "C:\Users\MAVIDIA\AppData\Local\Programs\Python\Python312\Lib\site-packages\redis\_parsers\socket.py", line 78, in _read_from_socket
    raise TimeoutError("Timeout reading from socket")
redis.exceptions.TimeoutError: Timeout reading from socket

During handling of the above exception, another exception occurred:

Traceback (most recent call last):
  File "C:\Users\MAVIDIA\AppData\Local\Programs\Python\Python312\Lib\site-packages\redis\_parsers\socket.py", line 65, in _read_from_socket
    data = self._sock.recv(socket_read_size)
           ^^^^^^^^^^^^^^^^^^^^^^^^^^^^^^^^^
TimeoutError: timed out

During handling of the above exception, another exception occurred:

Traceback (most recent call last):
  File "C:\Users\MAVIDIA\AppData\Local\Programs\Python\Python312\Lib\site-packages\kombu\connection.py", line 472, in _reraise_as_library_errors
    yield
  File "C:\Users\MAVIDIA\AppData\Local\Programs\Python\Python312\Lib\site-packages\celery\app\base.py", line 800, in send_task
    self.backend.on_task_call(P, task_id)
  File "C:\Users\MAVIDIA\AppData\Local\Programs\Python\Python312\Lib\site-packages\celery\backends\redis.py", line 373, in on_task_call
    self.result_consumer.consume_from(task_id)
  File "C:\Users\MAVIDIA\AppData\Local\Programs\Python\Python312\Lib\site-packages\celery\backends\redis.py", line 169, in consume_from
    return self.start(task_id)
           ^^^^^^^^^^^^^^^^^^^
  File "C:\Users\MAVIDIA\AppData\Local\Programs\Python\Python312\Lib\site-packages\celery\backends\redis.py", line 147, in start
    self._consume_from(initial_task_id)
  File "C:\Users\MAVIDIA\AppData\Local\Programs\Python\Python312\Lib\site-packages\celery\backends\redis.py", line 176, in _consume_from
    with self.reconnect_on_error():
         ^^^^^^^^^^^^^^^^^^^^^^^^^
  File "C:\Users\MAVIDIA\AppData\Local\Programs\Python\Python312\Lib\contextlib.py", line 158, in __exit__
    self.gen.throw(value)
  File "C:\Users\MAVIDIA\AppData\Local\Programs\Python\Python312\Lib\site-packages\celery\backends\redis.py", line 130, in reconnect_on_error
    self._ensure(self._reconnect_pubsub, ())
  File "C:\Users\MAVIDIA\AppData\Local\Programs\Python\Python312\Lib\site-packages\celery\backends\redis.py", line 384, in ensure
    return retry_over_time(
           ^^^^^^^^^^^^^^^^
  File "C:\Users\MAVIDIA\AppData\Local\Programs\Python\Python312\Lib\site-packages\kombu\utils\functional.py", line 318, in retry_over_time
    return fun(*args, **kwargs)
           ^^^^^^^^^^^^^^^^^^^^
  File "C:\Users\MAVIDIA\AppData\Local\Programs\Python\Python312\Lib\site-packages\celery\backends\redis.py", line 106, in _reconnect_pubsub
    metas = self.backend.client.mget(self.subscribed_to)
            ^^^^^^^^^^^^^^^^^^^^^^^^^^^^^^^^^^^^^^^^^^^^
  File "C:\Users\MAVIDIA\AppData\Local\Programs\Python\Python312\Lib\site-packages\redis\commands\core.py", line 2009, in mget
    return self.execute_command("MGET", *args, **options)
           ^^^^^^^^^^^^^^^^^^^^^^^^^^^^^^^^^^^^^^^^^^^^^^
  File "C:\Users\MAVIDIA\AppData\Local\Programs\Python\Python312\Lib\site-packages\redis\client.py", line 559, in execute_command
    return self._execute_command(*args, **options)
           ^^^^^^^^^^^^^^^^^^^^^^^^^^^^^^^^^^^^^^^
  File "C:\Users\MAVIDIA\AppData\Local\Programs\Python\Python312\Lib\site-packages\redis\client.py", line 565, in _execute_command
    conn = self.connection or pool.get_connection(command_name, **options)
                              ^^^^^^^^^^^^^^^^^^^^^^^^^^^^^^^^^^^^^^^^^^^^
  File "C:\Users\MAVIDIA\AppData\Local\Programs\Python\Python312\Lib\site-packages\redis\connection.py", line 1422, in get_connection
    connection.connect()
  File "C:\Users\MAVIDIA\AppData\Local\Programs\Python\Python312\Lib\site-packages\redis\connection.py", line 369, in connect
    self.on_connect()
  File "C:\Users\MAVIDIA\AppData\Local\Programs\Python\Python312\Lib\site-packages\redis\connection.py", line 471, in on_connect
    self.read_response()
  File "C:\Users\MAVIDIA\AppData\Local\Programs\Python\Python312\Lib\site-packages\redis\connection.py", line 592, in read_response
    response = self._parser.read_response(disable_decoding=disable_decoding)
               ^^^^^^^^^^^^^^^^^^^^^^^^^^^^^^^^^^^^^^^^^^^^^^^^^^^^^^^^^^^^^
  File "C:\Users\MAVIDIA\AppData\Local\Programs\Python\Python312\Lib\site-packages\redis\_parsers\resp2.py", line 15, in read_response
    result = self._read_response(disable_decoding=disable_decoding)
             ^^^^^^^^^^^^^^^^^^^^^^^^^^^^^^^^^^^^^^^^^^^^^^^^^^^^^^
  File "C:\Users\MAVIDIA\AppData\Local\Programs\Python\Python312\Lib\site-packages\redis\_parsers\resp2.py", line 25, in _read_response
    raw = self._buffer.readline()
          ^^^^^^^^^^^^^^^^^^^^^^^
  File "C:\Users\MAVIDIA\AppData\Local\Programs\Python\Python312\Lib\site-packages\redis\_parsers\socket.py", line 115, in readline
    self._read_from_socket()
  File "C:\Users\MAVIDIA\AppData\Local\Programs\Python\Python312\Lib\site-packages\redis\_parsers\socket.py", line 78, in _read_from_socket
    raise TimeoutError("Timeout reading from socket")
redis.exceptions.TimeoutError: Timeout reading from socket

The above exception was the direct cause of the following exception:

Traceback (most recent call last):
  File "C:\Users\MAVIDIA\AppData\Local\Programs\Python\Python312\Lib\site-packages\django\core\handlers\exception.py", line 55, in inner
    response = get_response(request)
               ^^^^^^^^^^^^^^^^^^^^^
  File "C:\Users\MAVIDIA\AppData\Local\Programs\Python\Python312\Lib\site-packages\django\core\handlers\base.py", line 197, in _get_response
    response = wrapped_callback(request, *callback_args, **callback_kwargs)
               ^^^^^^^^^^^^^^^^^^^^^^^^^^^^^^^^^^^^^^^^^^^^^^^^^^^^^^^^^^^^
  File "D:\Mavidia\projet\mon_projet\moodle\views.py", line 13, in trigger_fetch_users
    fetch_and_save_users.delay()
  File "C:\Users\MAVIDIA\AppData\Local\Programs\Python\Python312\Lib\site-packages\celery\app\task.py", line 444, in delay
    return self.apply_async(args, kwargs)
           ^^^^^^^^^^^^^^^^^^^^^^^^^^^^^^
  File "C:\Users\MAVIDIA\AppData\Local\Programs\Python\Python312\Lib\site-packages\celery\app\task.py", line 594, in apply_async
    return app.send_task(
           ^^^^^^^^^^^^^^
  File "C:\Users\MAVIDIA\AppData\Local\Programs\Python\Python312\Lib\site-packages\celery\app\base.py", line 798, in send_task
    with P.connection._reraise_as_library_errors():
         ^^^^^^^^^^^^^^^^^^^^^^^^^^^^^^^^^^^^^^^^^
  File "C:\Users\MAVIDIA\AppData\Local\Programs\Python\Python312\Lib\contextlib.py", line 158, in __exit__
    self.gen.throw(value)
  File "C:\Users\MAVIDIA\AppData\Local\Programs\Python\Python312\Lib\site-packages\kombu\connection.py", line 476, in _reraise_as_library_errors
    raise ConnectionError(str(exc)) from exc
kombu.exceptions.OperationalError: Timeout reading from socket
"GET /moodle/fetch-users/ HTTP/1.1" 500 276974
